2025-07-30 01:02:18,760 - INFO - WandB run initialized: HyperCLOVAX-SEED-Text-Instruct-1.5B_20250730_010217 (ID: 71bd7739)
Fetching 8 files:   0%|                                                                                                                       | 0/8 [00:00<?, ?it/s]
2025-07-30 01:02:19,631 - ERROR - [Process 2120894] Error in HyperCLOVAX-SEED-Text-Instruct-1.5B_harness_9: 401 Client Error. (Request ID: Root=1-68896f1b-59b01f6005fdf22e1732506e;430e6fdc-103b-4a0d-833f-5ea4969ef9c9)

Cannot access gated repo for url https://huggingface.co/naver-hyperclovax/HyperCLOVAX-SEED-Text-Instruct-1.5B/resolve/1ae9d346994979a4a1b58b7d312008dce449ba40/.gitattributes.
Access to model naver-hyperclovax/HyperCLOVAX-SEED-Text-Instruct-1.5B is restricted. You must have access to it and be authenticated to access it. Please log in.
Traceback (most recent call last):
  File "/home/gwlee/miniconda3/envs/science/lib/python3.10/site-packages/huggingface_hub/utils/_http.py", line 409, in hf_raise_for_status
    response.raise_for_status()
  File "/home/gwlee/miniconda3/envs/science/lib/python3.10/site-packages/requests/models.py", line 1024, in raise_for_status
    raise HTTPError(http_error_msg, response=self)
requests.exceptions.HTTPError: 401 Client Error: Unauthorized for url: https://huggingface.co/naver-hyperclovax/HyperCLOVAX-SEED-Text-Instruct-1.5B/resolve/1ae9d346994979a4a1b58b7d312008dce449ba40/.gitattributes

The above exception was the direct cause of the following exception:

Traceback (most recent call last):
  File "/home/gwlee/Benchmark/AIDE_Benchmark/code/core/evaluation_lm.py", line 630, in evaluate_single
    local_path = ensure_model_local(model_id)
  File "/home/gwlee/Benchmark/AIDE_Benchmark/code/core/evaluation_lm.py", line 149, in ensure_model_local
    local_path = snapshot_download(repo_id=repo_id, cache_dir=cache_dir, local_files_only=False)
  File "/home/gwlee/miniconda3/envs/science/lib/python3.10/site-packages/huggingface_hub/utils/_validators.py", line 114, in _inner_fn
    return fn(*args, **kwargs)
  File "/home/gwlee/miniconda3/envs/science/lib/python3.10/site-packages/huggingface_hub/_snapshot_download.py", line 296, in snapshot_download
    thread_map(
  File "/home/gwlee/miniconda3/envs/science/lib/python3.10/site-packages/tqdm/contrib/concurrent.py", line 69, in thread_map
    return _executor_map(ThreadPoolExecutor, fn, *iterables, **tqdm_kwargs)
  File "/home/gwlee/miniconda3/envs/science/lib/python3.10/site-packages/tqdm/contrib/concurrent.py", line 51, in _executor_map
    return list(tqdm_class(ex.map(fn, *iterables, chunksize=chunksize), **kwargs))
  File "/home/gwlee/miniconda3/envs/science/lib/python3.10/site-packages/tqdm/std.py", line 1181, in __iter__
    for obj in iterable:
  File "/home/gwlee/miniconda3/envs/science/lib/python3.10/concurrent/futures/_base.py", line 621, in result_iterator
    yield _result_or_cancel(fs.pop())
  File "/home/gwlee/miniconda3/envs/science/lib/python3.10/concurrent/futures/_base.py", line 319, in _result_or_cancel
    return fut.result(timeout)
  File "/home/gwlee/miniconda3/envs/science/lib/python3.10/concurrent/futures/_base.py", line 458, in result
    return self.__get_result()
  File "/home/gwlee/miniconda3/envs/science/lib/python3.10/concurrent/futures/_base.py", line 403, in __get_result
    raise self._exception
  File "/home/gwlee/miniconda3/envs/science/lib/python3.10/concurrent/futures/thread.py", line 58, in run
    result = self.fn(*self.args, **self.kwargs)
  File "/home/gwlee/miniconda3/envs/science/lib/python3.10/site-packages/huggingface_hub/_snapshot_download.py", line 270, in _inner_hf_hub_download
    return hf_hub_download(
  File "/home/gwlee/miniconda3/envs/science/lib/python3.10/site-packages/huggingface_hub/utils/_validators.py", line 114, in _inner_fn
    return fn(*args, **kwargs)
  File "/home/gwlee/miniconda3/envs/science/lib/python3.10/site-packages/huggingface_hub/file_download.py", line 961, in hf_hub_download
    return _hf_hub_download_to_cache_dir(
  File "/home/gwlee/miniconda3/envs/science/lib/python3.10/site-packages/huggingface_hub/file_download.py", line 1068, in _hf_hub_download_to_cache_dir
    _raise_on_head_call_error(head_call_error, force_download, local_files_only)
  File "/home/gwlee/miniconda3/envs/science/lib/python3.10/site-packages/huggingface_hub/file_download.py", line 1596, in _raise_on_head_call_error
    raise head_call_error
  File "/home/gwlee/miniconda3/envs/science/lib/python3.10/site-packages/huggingface_hub/file_download.py", line 1484, in _get_metadata_or_catch_error
    metadata = get_hf_file_metadata(
  File "/home/gwlee/miniconda3/envs/science/lib/python3.10/site-packages/huggingface_hub/utils/_validators.py", line 114, in _inner_fn
    return fn(*args, **kwargs)
  File "/home/gwlee/miniconda3/envs/science/lib/python3.10/site-packages/huggingface_hub/file_download.py", line 1401, in get_hf_file_metadata
    r = _request_wrapper(
  File "/home/gwlee/miniconda3/envs/science/lib/python3.10/site-packages/huggingface_hub/file_download.py", line 285, in _request_wrapper
    response = _request_wrapper(
  File "/home/gwlee/miniconda3/envs/science/lib/python3.10/site-packages/huggingface_hub/file_download.py", line 309, in _request_wrapper
    hf_raise_for_status(response)
  File "/home/gwlee/miniconda3/envs/science/lib/python3.10/site-packages/huggingface_hub/utils/_http.py", line 426, in hf_raise_for_status
    raise _format(GatedRepoError, message, response) from e
huggingface_hub.errors.GatedRepoError: 401 Client Error. (Request ID: Root=1-68896f1b-59b01f6005fdf22e1732506e;430e6fdc-103b-4a0d-833f-5ea4969ef9c9)

Cannot access gated repo for url https://huggingface.co/naver-hyperclovax/HyperCLOVAX-SEED-Text-Instruct-1.5B/resolve/1ae9d346994979a4a1b58b7d312008dce449ba40/.gitattributes.
Access to model naver-hyperclovax/HyperCLOVAX-SEED-Text-Instruct-1.5B is restricted. You must have access to it and be authenticated to access it. Please log in.
